Workbook

Sheet COLC
A1: Item | B1: No Of Item | C1: Mandays | D1: Remarks

Sheet CIC (New)
A1: Item | B1: No Of Item | C1: Time Spent (mins) | D1: Breakdown Mandays | E1: Config Item | F1: Remark | G1: Mandays
A2: Event | B2: 1 | C2: 5 | D2: =ROUNDUP(C2/480,2) -> 0.02 | E2: Event Details | F2: Configure event details (parameters) | G2: =SUM(D2) -> 0.02
A3: Flow | B3: 1 | C3: 5 | D3: =ROUNDUP(C3/480,2) -> 0.02 | E3: Flow Condition | F3: Configure flow condition | G3: =SUM(D3:D7) -> 0.1
B4: 1 | C4: 2 | D4: =ROUNDUP(C4/480,2) -> 0.01 | E4: Judgement Rule | F4: Configure judgement rule(s)
B5: 1 | C5: 5 | D5: =ROUNDUP(C5/480,2) -> 0.02 | E5: Set Specified Members | F5: Configure specified members (subarray)
B6: 1 | C6: 2 | D6: =ROUNDUP(C6/480,2) -> 0.01 | E6: Query | F6: Configure query (to get data from specific table)
B7: 1 | C7: 15 | D7: =ROUNDUP(C7/480,2) -> 0.04 | E7: Outbound Message (Process) | F7: Configure Email/ SMS/ Web Message/ Whatsapp
A8: Config Data | B8: 1 | C8: 2 | D8: =ROUNDUP(C8/480,2) -> 0.01 | E8: Config Data | F8: Configure config data (additional parameter) | G8: =SUM(D8) -> 0.01

Sheet CSC(New)
A1: Item | B1: No Of Item | C1: Time Spent (mins) | D1: Breakdown Mandays | E1: Config Item | F1: Remark | G1: Mandays
A2: Service Type Management | B2: 1 | C2: 5 | D2: =ROUNDUP(C2/480,2) -> 0.02 | E2: Service Type Name | F2: Configure service type details (repetitive) | G2: =SUM(D2:D4) -> 0.07
B3: 1 | C3: 15 | D3: =ROUNDUP(C3/480,2) -> 0.04 | F3: Configure feature (repetitive)
B4: 1 | C4: 2 | D4: =ROUNDUP(C4/480,2) -> 0.01 | F4: Configure workflow rule (repetitive)
A5: Workflow Template | B5: 1 | C5: 2 | D5: =ROUNDUP(C5/480,2) -> 0.01 | E5: Assignment Process | F5: Configure process name | G5: =SUM(D5:D6) -> 0.02
B6: 1 | C6: 2 | D6: =ROUNDUP(C6/480,2) -> 0.01 | F6: Configure workflow
A7: Activity Rule | B7: 1 | C7: 2 | D7: =ROUNDUP(C7/480,2) -> 0.01 | E7: Dispatch Rule | F7: Configure dispatch rule | G7: 0.01
A8: Activity Template | B8: 1 | C8: 2 | D8: =ROUNDUP(C8/480,2) -> 0.01 | E8: Activity Name | F8: Configure activity name | G8: 0.01
A9: Closure Reason | B9: 1 | C9: 2 | D9: =ROUNDUP(C9/480,2) -> 0.01 | E9: Event Name | F9: Configure reason name and code | G9: 0.01
A10: Configuration Parameter | B10: 1 | C10: 2 | D10: =ROUNDUP(C10/480,2) -> 0.01 | E10: Configuration Parameter | F10: Configure parameter(s) | G10: 0.01

Sheet CPC (New)
A1: Item | B1: No Of Item | C1: Time Spent (mins) | D1: Breakdown Mandays | E1: Config Item | F1: Remarks | G1: Mandays
A2: Assessment | B2: 1 | C2: 20 | D2: =ROUND(C2/480,3) -> 0.042 | E2: Assessment | F2: Per detect | G2: =SUM(D2) -> 0.042
A3: Bundle Offer | B3: 1 | C3: 1 | D3: =ROUND(C3/480,3) -> 0.002 | E3: Base Information LifeCycle Apply Offer Version | F3: Configure basic information for bundle offer Configure offer version effective/expiry date | G3: =SUM(D3:D15) -> 0.255
C4: 5 | D4: =ROUND(C4/480,3) -> 0.01 | E4: Offer Group (bundle level) | F4: Configure additional offer at bundle level (convergence discount, rebate, etc) Configure offer group in Offer Group view
C5: 10 | D5: =ROUND(C5/480,3) -> 0.021 | E5: Bundle Member Bundle Restrict Rule | F5: Configure bundle members in bundle offer
C6: 30 | D6: =ROUND(C6/480,3) -> 0.063 | E6: Bundle Member Group | F6: Configure customized offer groups under bundle member
C7: 1 | D7: =ROUND(C7/480,3) -> 0.002 | E7: Offer Attribute | F7: Configure bundle attributes
C8: 60 | D8: =ROUND(C8/480,3) -> 0.125 | E8: Offer Relationship | F8: Configure bundle offer relationship
C9: 5 | D9: =ROUND(C9/480,3) -> 0.01 | E9: Sales Condition | F9: Configure sales area, sales channel, member sales channel, sales group
C10: 1 | D10: =ROUND(C10/480,3) -> 0.002 | E10: Price For Tariff | F10: Configure tariff plan parameter Configure offer price parameter
C11: 1 | D11: =ROUND(C11/480,3) -> 0.002 | E11: Advanced Sales Condition | F11: Configure specific rule in Rule Event View
C12: 2 | D12: =ROUND(C12/480,3) -> 0.004 | E12: Quantity Limit | F12: Configure limit rule in Time Limit Rule Management view
C13: 5 | D13: =ROUND(C13/480,3) -> 0.01 | E13: Sales Permissions | F13: Configure sales role, sales organization, sales staff
C14: 1 | D14: =ROUND(C14/480,3) -> 0.002 | E14: Notification Configuration | F14: Configure KCI for offer expiry
C15: 1 | D15: =ROUND(C15/480,3) -> 0.002 | E15: Agreement Restrict | F15: Configure agreement
A16: Main Offer | B16: 1 | C16: 1 | D16: =ROUND(C16/480,3) -> 0.002 | E16: Base Information Lifecycle Type Offer Version | F16: Configure basic information for main offer Configure offer version effective/expiry date | G16: =SUM(D16:D28) -> 0.142
C17: 5 | D17: =ROUND(C17/480,3) -> 0.01 | E17: Product Specification | F17: Configure main offer association with main product and attributes
C18: 30 | D18: =ROUND(C18/480,3) -> 0.063 | E18: Offer Group | F18: Configure additional offer in main offer Configure offer group in Offer Group view
C19: 5 | D19: =ROUND(C19/480,3) -> 0.01 | E19: Sales Condition | F19: Configure sales area, sales channel, member sales channel, sales group
C20: 15 | D20: =ROUND(C20/480,3) -> 0.031 | E20: Offer Relationship | F20: Configure main offer relationship
C21: 1 | D21: =ROUND(C21/480,3) -> 0.002 | E21: Price for Tariff | F21: Configure tariff plan parameter Configure offer price parameter
C22: 1 | D22: =ROUND(C22/480,3) -> 0.002 | E22: Offer Attribute | F22: Configure main offer attributes
C23: 1 | D23: =ROUND(C23/480,3) -> 0.002 | E23: Price for OTC | F23: Configure price plan in One Time Charge > Price Plan view
C24: 1 | D24: =ROUND(C24/480,3) -> 0.002 | E24: Advanced Sales Condition | F24: Configure specific rule in Rule Event View
C25: 5 | D25: =ROUND(C25/480,3) -> 0.01 | E25: Sales Permissions | F25: Configure sales role, sales organization, sales staff
C26: 1 | D26: =ROUND(C26/480,3) -> 0.002 | E26: Notification Configuration | F26: Configure KCI for offer expiry
C27: 2 | D27: =ROUND(C27/480,3) -> 0.004 | E27: Quantity Limit | F27: Configure limit rule in Time Limit Rule Management view
C28: 1 | D28: =ROUND(C28/480,3) -> 0.002 | E28: Agreement Restrict | F28: Configure agreement
A29: Additional Offer | B29: 1 | C29: 1 | D29: =ROUND(C29/480,3) -> 0.002 | E29: Base Information Lifecycle Type | F29: Configure basic information for additional offer Configure offer version effective/expiry date | G29: =SUM(D29:D41) -> 0.066
C30: 1 | D30: =ROUND(C30/480,3) -> 0.002 | E30: Offer Attribute | F30: Configure additional offer attributes
C31: 5 | D31: =ROUND(C31/480,3) -> 0.01 | E31: Product Specification | F31: Configure additional offer association with main product and attributes
C32: 5 | D32: =ROUND(C32/480,3) -> 0.01 | E32: Sales Condition | F32: Configure sales area, sales channel, member sales channel, sales group
C33: 1 | D33: =ROUND(C33/480,3) -> 0.002 | E33: Price for Tariff | F33: Configure tariff plan parameter Configure offer price parameter
C34: 1 | D34: =ROUND(C34/480,3) -> 0.002 | E34: Price for OTC | F34: Add OTC to offer
C35: 5 | D35: =ROUND(C35/480,3) -> 0.01 | E35: Offer Relationship | F35: Configure additional offer relationship
C36: 1 | D36: =ROUND(C36/480,3) -> 0.002 | E36: Belong in Offer Group | F36: Configure additional offer in main offer Configure offer group in Offer Group view
C37: 5 | D37: =ROUND(C37/480,3) -> 0.01 | E37: Package | F37: Configure additional offer included as package
C38: 1 | D38: =ROUND(C38/480,3) -> 0.002 | E38: Quantity Limit | F38: Configure limit rule in Time Limit Rule Management view
C39: 5 | D39: =ROUND(C39/480,3) -> 0.01 | E39: Sales Permissions | F39: Configure sales role, sales organization, sales staff
C40: 1 | D40: =ROUND(C40/480,3) -> 0.002 | E40: Notification Configuration | F40: Configure KCI for offer expiry
...

Sheet JNC (New)
A2: No | B2: Item | C2: Duration (Min) | D2: Mandays | E2: Config Item
A3: 1 | B3: Balance / Account Item Type | C3: 5 | D3: =ROUNDUP(C3/480,2) -> 0.02 | E3: To create a new account item type. To filled up account item type name, account balance type, adjust catg, etc
A4: 2 | B4: Consumption Type | C4: 2 | D4: =ROUNDUP(C4/480,2) -> 0.01 | E4: To create a new consumption type that tie to the account item type. This consumption type will be used by CPC to create price plan/tarrif plan/otc
A5: 3 | B5: Merge | C5: 20 | D5: =ROUNDUP(C5/480,2) -> 0.05 | E5: Bill format merging is to define the account item type's charge section in bill. E.g monthly charge, other charge, discounts
A6: 4 | B6: Tax code S8/NT | C6: 10 | D6: =ROUNDUP(C6/480,2) -> 0.03 | E6: To configure the tax code of the account item type. Tax code for ST is default, no need to configure. NT and S8 need to configure
A7: 5 | B7: Apportion Recurring and Apportion Discount | C7: 15 | D7: =ROUNDUP(C7/480,2) -> 0.04 | E7: To configure the apportion rule for discount/rebate/waiver
A8: 6 | B8: Adjustment mapping rule | C8: 120 | D8: =ROUNDUP(C8/480,2) -> 0.25 | E8: To configure the adjustment mapping rule for journal (BA and UBA)
A9: 7 | B9: GL mapping rule | C9: 120 | D9: =ROUNDUP(C9/480,2) -> 0.25 | E9: To configure the GL mapping rule for journal (BE, UBE, BUE, OCR)
A10: 8 | B10: Journal rule condition | C10: 30 | D10: =ROUNDUP(C10/480,2) -> 0.07 | E10: To configure the condition for discount/rebate/waiver without journal UBE and BUE
A11: 9 | B11: Apportion rule | C11: 15 | D11: =ROUNDUP(C11/480,2) -> 0.04 | E11: To configure the bundle splitting
A12: 10 | B12: Fair apportion object | C12: 10 | D12: =ROUNDUP(C12/480,2) -> 0.03 | E12: To configure fair apportion object
A13: 11 | B13: Fair apportion catalog | C13: 10 | D13: =ROUNDUP(C13/480,2) -> 0.03 | E13: To configure fair apportion catalog
A14: 12 | B14: Journal rule for one time charge | C14: 30 | D14: =ROUNDUP(C14/480,2) -> 0.07 | E14: To configure journal rule for OTC payment type
A15: 13 | B15: Exclusion of Account Item Type from normal journal workflow | C15: 30 | D15: 0.07 | E15: To configure the condition to exclude the Account Item Type from the Account Attribute validation againts the Cost Center and Profit Center mapping rules
A16: 14 | B16: Bill template | C16: 30 | D16: =ROUNDUP(C16/480,2) -> 0.07 | E16: To configure bill template for bill presentment
A17: 15 | B17: UT | C17: 5 | D17: =ROUNDUP(C17/480,2) -> 0.02 | E17: UT
A18: 16 | B18: Account Item Group | C18: 5 | D18: 0.02 | E18: To update existing Account Item Group
A19: 17 | C19: 20 | D19: 0.05 | E19: To create new Account Item Group
